Workbook

Sheet Global
A2: Global Liquid Biopsy Market, 2027-36 (USD Million)
D12: =D14='Market Analysis '!C8 -> TRUE | E12: =E14='Market Analysis '!D8 -> TRUE | F12: =F14='Market Analysis '!E8 -> TRUE | G12: =G14='Market Analysis '!F8 -> TRUE | H12: =H14='Market Analysis '!G8 -> TRUE | I12: =I14='Market Analysis '!H8 -> TRUE | J12: =J14='Market Analysis '!I8 -> TRUE | K12: =K14='Market Analysis '!J8 -> TRUE | ... Q12: =Q14='Market Analysis '!P8 -> TRUE
D13: 2023 | E13: 2024 | F13: 2025 | G13: 2026 | H13: 2027 | I13: 2028 | J13: 2029 | K13: 2030 | L13: 2031 | M13: 2032 | N13: 2033 | O13: 2034 | P13: 2035 | Q13: 2036 | R13: CAGR (2027-2036)
D14: ='Market Analysis '!C11+'Market Analysis '!C17+'Market Analysis '!C35+'Market Analysis '!C45+'Market Analysis '!C57 -> 4589 | E14: ='Market Analysis '!D11+'Market Analysis '!D17+'Market Analysis '!D35+'Market Analysis '!D45+'Market Analysis '!D57 -> 5133.736 | F14: ='Market Analysis '!E11+'Market Analysis '!E17+'Market Analysis '!E35+'Market Analysis '!E45+'Market Analysis '!E57 -> 5753.0666 | G14: ='Market Analysis '!F11+'Market Analysis '!F17+'Market Analysis '!F35+'Market Analysis '!F45+'Market Analysis '!F57 -> 6458.3341 | H14: ='Market Analysis '!G11+'Market Analysis '!G17+'Market Analysis '!G35+'Market Analysis '!G45+'Market Analysis '!G57 -> 7262.7698 | I14: ='Market Analysis '!H11+'Market Analysis '!H17+'Market Analysis '!H35+'Market Analysis '!H45+'Market Analysis '!H57 -> 8181.8372 | J14: ='Market Analysis '!I11+'Market Analysis '!I17+'Market Analysis '!I35+'Market Analysis '!I45+'Market Analysis '!I57 -> 9233.6418 | K14: ='Market Analysis '!J11+'Market Analysis '!J17+'Market Analysis '!J35+'Market Analysis '!J45+'Market Analysis '!J57 -> 10439.423 | ... Q14: ='Market Analysis '!P11+'Market Analysis '!P17+'Market Analysis '!P35+'Market Analysis '!P45+'Market Analysis '!P57 -> 22669.973 | R14: =RATE(9,,-H14,Q14) -> 0.13482171 | T14: 2023 | U14: 2024 | V14: 2025 | W14: 2026 | X14: 2027 | Y14: 2028 | Z14: 2029 | AA14: 2030 | AB14: 2031 | AC14: 2032 | AD14: 2033 | AE14: 2034 | AF14: 2035 | AG14: 2036
A15: Biomarker Type | B15: Circulating tumor cells | D15: =D14*T15 -> 1376.7 | E15: =E14*U15 -> 1558.4919 | F15: =F14*V15 -> 1767.3402 | G15: =G14*W15 -> 2007.6639 | H15: =H14*X15 -> 2284.6651 | I15: =I14*Y15 -> 2604.479 | J15: =J14*Z15 -> 2974.355 | K15: =K14*AA15 -> 3402.8753 | ... Q15: =Q14*AG15 -> 7934.4907 | R15: =RATE(9,,-H15,Q15) -> 0.14835824 | S15: Circulating tumor cells | T15: 0.3 | U15: 0.3035785 | V15: 0.30719968 | W15: 0.31086406 | X15: 0.31457215 | Y15: 0.31832447 | Z15: 0.32212154 | AA15: 0.32596392 | AB15: 0.32985212 | AC15: 0.3337867 | AD15: 0.33776822 | AE15: 0.34179723 | AF15: 0.3458743 | AG15: 0.35
B16: Circulating tumor DNA | D16: =D14*T16 -> 917.8 | E16: =E14*U16 -> 1030.6079 | F16: =F14*V16 -> 1159.2825 | G16: =G14*W16 -> 1306.2922 | H16: =H14*X16 -> 1474.5247 | I16: =I14*Y16 -> 1667.3645 | J16: =J14*Z16 -> 1888.7857 | K16: =K14*AA16 -> 2143.4637 | ... Q16: =Q14*AG16 -> 4760.6944 | R16: =RATE(9,,-H16,Q16) -> 0.1390888 | S16: Circulating tumor DNA | T16: 0.2 | U16: 0.20075203 | V16: 0.20150688 | W16: 0.20226458 | X16: 0.20302512 | Y16: 0.20378853 | Z16: 0.2045548 | AA16: 0.20532395 | AB16: 0.206096 | AC16: 0.20687095 | AD16: 0.20764881 | AE16: 0.2084296 | AF16: 0.20921333 | AG16: 0.21
B17: Exosomes | D17: =D14*T17 -> 458.9 | E17: =E14*U17 -> 520.62425 | F17: =F14*V17 -> 591.67216 | G17: =G14*W17 -> 673.58608 | H17: =H14*X17 -> 768.18485 | I17: =I14*Y17 -> 877.61726 | J17: =J14*Z17 -> 1004.4266 | K17: =K14*AA17 -> 1151.6289 | ... Q17: =Q14*AG17 -> 2720.3968 | R17: =RATE(9,,-H17,Q17) -> 0.15084942 | S17: Exosomes | T17: 0.1 | U17: 0.10141235 | V17: 0.10284466 | W17: 0.10429719 | X17: 0.10577023 | Y17: 0.10726408 | Z17: 0.10877903 | AA17: 0.11031538 | AB17: 0.11187342 | AC17: 0.11345347 | AD17: 0.11505584 | AE17: 0.11668083 | AF17: 0.11832878 | AG17: 0.12
B18: Circulating RNA & proteins | D18: =D14*T18 -> 321.23 | E18: =E14*U18 -> 361.27377 | F18: =F14*V18 -> 407.01196 | G18: =G14*W18 -> 459.33881 | H18: =H14*X18 -> 519.30173 | I18: =I14*Y18 -> 588.1298 | J18: =J14*Z18 -> 667.26792 | K18: =K14*AA18 -> 758.41793 | ... Q18: =Q14*AG18 -> 1700.248 | R18: =RATE(9,,-H18,Q18) -> 0.14086039 | S18: Circulating RNA & proteins | T18: 0.07 | U18: 0.070372488 | V18: 0.070746957 | W18: 0.07112342 | X18: 0.071501885 | Y18: 0.071882365 | Z18: 0.072264869 | AA18: 0.072649409 | AB18: 0.073035994 | AC18: 0.073424637 | AD18: 0.073815348 | AE18: 0.074208138 | AF18: 0.074603019 | AG18: 0.075
B19: Nucleosomes | D19: =D14*T19 -> 1514.37 | E19: =E14*U19 -> 1662.7382 | F19: =F14*V19 -> 1827.7597 | G19: =G14*W19 -> 2011.453 | H19: =H14*X19 -> 2216.0934 | I19: =I14*Y19 -> 2444.2466 | J19: =J14*Z19 -> 2698.8066 | K19: =K14*AA19 -> 2983.0375 | ... Q19: =Q14*AG19 -> 5554.1435 | R19: =RATE(9,,-H19,Q19) -> 0.1074817 | S19: Nucleosomes | T19: =1-SUM(T15:T18) -> 0.33 | U19: =1-SUM(U15:U18) -> 0.32388463 | V19: =1-SUM(V15:V18) -> 0.31770182 | W19: =1-SUM(W15:W18) -> 0.31145076 | X19: =1-SUM(X15:X18) -> 0.30513061 | Y19: =1-SUM(Y15:Y18) -> 0.29874056 | Z19: =1-SUM(Z15:Z18) -> 0.29227976 | AA19: =1-SUM(AA15:AA18) -> 0.28574734 | ... AG19: =1-SUM(AG15:AG18) -> 0.245
D20: =D14=SUM(D15:D19) -> TRUE | E20: =E14=SUM(E15:E19) -> TRUE | F20: =F14=SUM(F15:F19) -> TRUE | G20: =G14=SUM(G15:G19) -> TRUE | H20: =H14=SUM(H15:H19) -> TRUE | I20: =I14=SUM(I15:I19) -> TRUE | J20: =J14=SUM(J15:J19) -> TRUE | K20: =K14=SUM(K15:K19) -> TRUE | ... Q20: =Q14=SUM(Q15:Q19) -> TRUE
A21: Sample | B21: Blood | D21: =D14*T21 -> 3212.3 | E21: =E14*U21 -> 3594.0101 | F21: =F14*V21 -> 4028.0317 | G21: =G14*W21 -> 4522.3242 | H21: =H14*X21 -> 5086.1735 | I21: =I14*Y21 -> 5730.4329 | J21: =J14*Z21 -> 6467.811 | K21: =K14*AA21 -> 7313.2175 | ... Q21: =Q14*AG21 -> 15891.651 | R21: =RATE(9,,-H21,Q21) -> 0.13494631 | S21: Blood | T21: 0.7 | U21: 0.70007692 | V21: 0.70015385 | W21: 0.70023077 | X21: 0.70030769 | Y21: 0.70038462 | Z21: 0.70046154 | AA21: 0.70053846 | AB21: 0.70061538 | AC21: 0.70069231 | AD21: 0.70076923 | AE21: 0.70084615 | AF21: 0.70092308 | AG21: 0.701
B22: Urine | D22: =D14*T22 -> 917.8 | E22: =E14*U22 -> 1027.1421 | F22: =F14*V22 -> 1151.4984 | G22: =G14*W22 -> 1293.1572 | H22: =H14*X22 -> 1454.7887 | I22: =I14*Y22 -> 1639.5143 | J22: =J14*Z22 -> 1850.99 | K22: =K14*AA22 -> 2093.5059 | ... Q22: =Q14*AG22 -> 4556.6647 | R22: =RATE(9,,-H22,Q22) -> 0.13525685 | S22: Urine | T22: 0.2 | U22: 0.20007692 | V22: 0.20015385 | W22: 0.20023077 | X22: 0.20030769 | Y22: 0.20038462 | Z22: 0.20046154 | AA22: 0.20053846 | AB22: 0.20061538 | AC22: 0.20069231 | AD22: 0.20076923 | AE22: 0.20084615 | AF22: 0.20092308 | AG22: 0.201
B23: Others (Serum) | D23: =D14*T23 -> 458.9 | E23: =E14*U23 -> 512.58379 | F23: =F14*V23 -> 573.53649 | G23: =G14*W23 -> 642.85264 | H23: =H14*X23 -> 721.80758 | I23: =I14*Y23 -> 811.89 | J23: =J14*Z23 -> 914.84082 | K23: =K14*AA23 -> 1032.6999 | ... Q23: =Q14*AG23 -> 2221.6574 | R23: =RATE(9,,-H23,Q23) -> 0.13305405 | S23: Others (Serum) | T23: =1-SUM(T21:T22) -> 0.1 | U23: =1-SUM(U21:U22) -> 0.099846154 | V23: =1-SUM(V21:V22) -> 0.099692308 | W23: =1-SUM(W21:W22) -> 0.099538462 | X23: =1-SUM(X21:X22) -> 0.099384615 | Y23: =1-SUM(Y21:Y22) -> 0.099230769 | Z23: =1-SUM(Z21:Z22) -> 0.099076923 | AA23: =1-SUM(AA21:AA22) -> 0.098923077 | ... AG23: =1-SUM(AG21:AG22) -> 0.098
D24: =D14=SUM(D21:D23) -> TRUE | E24: =E14=SUM(E21:E23) -> TRUE | F24: =F14=SUM(F21:F23) -> TRUE | G24: =G14=SUM(G21:G23) -> TRUE | H24: =H14=SUM(H21:H23) -> TRUE | I24: =I14=SUM(I21:I23) -> FALSE | J24: =J14=SUM(J21:J23) -> FALSE | K24: =K14=SUM(K21:K23) -> TRUE | ... Q24: =Q14=SUM(Q21:Q23) -> TRUE
A25: Clinical Application | B25: Early disease screening | D25: =D14*T25 -> 1376.7 | E25: =E14*U25 -> 1552.5342 | F25: =F14*V25 -> 1753.8539 | G25: =G14*W25 -> 1984.7276 | H25: =H14*X25 -> 2249.9303 | I25: =I14*Y25 -> 2555.0771 | J25: =J14*Z25 -> 2906.7828 | K25: =K14*AA25 -> 3312.8551 | ... Q25: =Q14*AG25 -> 7549.1012 | R25: =RATE(9,,-H25,Q25) -> 0.14396838 | S25: Early disease screening | T25: 0.3 | U25: 0.302418 | V25: 0.30485549 | W25: 0.30731263 | X25: 0.30978957 | Y25: 0.31228647 | Z25: 0.3148035 | AA25: 0.31734082 | AB25: 0.31989858 | AC25: 0.32247697 | AD25: 0.32507613 | AE25: 0.32769625 | AF25: 0.33033748 | AG25: 0.333
B26: Therapy selection | D26: =D14*T26 -> 917.8 | E26: =E14*U26 -> 1034.3025 | F26: =F14*V26 -> 1167.6092 | G26: =G14*W26 -> 1320.3913 | H26: =H14*X26 -> 1495.7826 | I26: =I14*Y26 -> 1697.466 | J26: =J14*Z26 -> 1929.7779 | K26: =K14*AA26 -> 2197.8339 | ... Q26: =Q14*AG26 -> 4987.3942 | R26: =RATE(9,,-H26,Q26) -> 0.14317229 | S26: Therapy selection | T26: 0.2 | U26: 0.2014717 | V26: 0.20295423 | W26: 0.20444766 | X26: 0.20595209 | Y26: 0.20746759 | Z26: 0.20899424 | AA26: 0.21053212 | AB26: 0.21208132 | AC26: 0.21364192 | AD26: 0.215214 | AE26: 0.21679765 | AF26: 0.21839296 | AG26: 0.22
B27: Treatment response monitoring | D27: =D14*T27 -> 688.35 | E27: =E14*U27 -> 775.72688 | F27: =F14*V27 -> 875.70689 | G27: =G14*W27 -> 990.29349 | H27: =H14*X27 -> 1121.837 | I27: =I14*Y27 -> 1273.0995 | J27: =J14*Z27 -> 1447.3334 | K27: =K14*AA27 -> 1648.3754 | ... Q27: =Q14*AG27 -> 3740.5456 | R27: =RATE(9,,-H27,Q27) -> 0.14317229 | S27: Treatment response monitoring | T27: 0.15 | U27: 0.15110377 | V27: 0.15221567 | W27: 0.15333575 | X27: 0.15446407 | Y27: 0.15560069 | Z27: 0.15674568 | AA27: 0.15789909 | AB27: 0.15906099 | AC27: 0.16023144 | AD27: 0.1614105 | AE27: 0.16259824 | AF27: 0.16379472 | AG27: 0.165
B28: Molecular health monitoring | D28: =D14*T28 -> 321.23 | E28: =E14*U28 -> 361.27377 | F28: =F14*V28 -> 407.01196 | G28: =G14*W28 -> 459.33881 | H28: =H14*X28 -> 519.30173 | I28: =I14*Y28 -> 588.1298 | J28: =J14*Z28 -> 667.26792 | K28: =K14*AA28 -> 758.41793 | ... Q28: =Q14*AG28 -> 1700.248 | R28: =RATE(9,,-H28,Q28) -> 0.14086039 | S28: Molecular health monitoring | T28: 0.07 | U28: 0.070372488 | V28: 0.070746957 | W28: 0.07112342 | X28: 0.071501885 | Y28: 0.071882365 | Z28: 0.072264869 | AA28: 0.072649409 | AB28: 0.073035994 | AC28: 0.073424637 | AD28: 0.073815348 | AE28: 0.074208138 | AF28: 0.074603019 | AG28: 0.075
B29: Others | D29: =D14*T29 -> 1284.92 | E29: =E14*U29 -> 1409.8986 | F29: =F14*V29 -> 1548.8846 | G29: =G14*W29 -> 1703.5829 | H29: =H14*X29 -> 1875.9182 | I29: =I14*Y29 -> 2068.0648 | J29: =J14*Z29 -> 2282.4798 | K29: =K14*AA29 -> 2521.9409 | ... Q29: =Q14*AG29 -> 4692.6845 | R29: =RATE(9,,-H29,Q29) -> 0.10724894 | S29: Others | T29: =1-SUM(T25:T28) -> 0.28 | U29: =1-SUM(U25:U28) -> 0.27463404 | V29: =1-SUM(V25:V28) -> 0.26922766 | W29: =1-SUM(W25:W28) -> 0.26378054 | X29: =1-SUM(X25:X28) -> 0.25829239 | Y29: =1-SUM(Y25:Y28) -> 0.25276288 | Z29: =1-SUM(Z25:Z28) -> 0.24719171 | AA29: =1-SUM(AA25:AA28) -> 0.24157856 | ... AG29: =1-SUM(AG25:AG28) -> 0.207
D30: =D14=SUM(D25:D29) -> TRUE | E30: =E14=SUM(E25:E29) -> TRUE | F30: =F14=SUM(F25:F29) -> TRUE | G30: =G14=SUM(G25:G29) -> TRUE | H30: =H14=SUM(H25:H29) -> TRUE | I30: =I14=SUM(I25:I29) -> TRUE | J30: =J14=SUM(J25:J29) -> TRUE | K30: =K14=SUM(K25:K29) -> TRUE | ... Q30: =Q14=SUM(Q25:Q29) -> TRUE
A31: Disease Indication | B31: Lung cancer | D31: =D14*T31 -> 1147.25 | E31: =E14*U31 -> 1270.8754 | F31: =F14*V31 -> 1410.2571 | G31: =G14*W31 -> 1567.649 | H31: =H14*X31 -> 1745.6615 | I31: =I14*Y31 -> 1947.3231 | J31: =J14*Z31 -> 2176.1541 | K31: =K14*AA31 -> 2436.254 | ... Q31: =Q14*AG31 -> 4987.3942 | R31: =RATE(9,,-H31,Q31) -> 0.12371732 | S31: Lung cancer | T31: 0.25 | U31: 0.24755371 | V31: 0.24513136 | W31: 0.24273272 | X31: 0.24035754 | Y31: 0.23800561 | Z31: 0.23567669 | AA31: 0.23337056 | AB31: 0.23108699 | AC31: 0.22882577 | AD31: 0.22658668 | AE31: 0.22436949 | AF31: 0.22217401 | AG31: 0.22
B32: Colorectal cancer | D32: =D14*T32 -> 917.8 | E32: =E14*U32 -> 1032.475 | F32: =F14*V32 -> 1163.4868 | G32: =G14*W32 -> 1313.4048 | H32: =H14*X32 -> 1485.2392 | I32: =I14*Y32 -> 1682.523 | J32: =J14*Z32 -> 1909.4102 | K32: =K14*AA32 -> 2170.7947 | ... Q32: =Q14*AG32 -> 4874.0443 | R32: =RATE(9,,-H32,Q32) -> 0.14115247 | S32: Colorectal cancer | T32: 0.2 | U32: 0.20111573 | V32: 0.20223768 | W32: 0.20336589 | X32: 0.20450039 | Y32: 0.20564122 | Z32: 0.20678842 | AA32: 0.20794201 | AB32: 0.20910205 | AC32: 0.21026855 | AD32: 0.21144156 | AE32: 0.21262111 | AF32: 0.21380725 | AG32: 0.215
B33: Breast cancer | D33: =D14*T33 -> 826.02 | E33: =E14*U33 -> 924.85826 | F33: =F14*V33 -> 1037.3139 | G33: =G14*W33 -> 1165.4682 | H33: =H14*X33 -> 1311.7509 | I33: =I14*Y33 -> 1479.003 | J33: =J14*Z33 -> 1670.5535 | K33: =K14*AA33 -> 1890.31 | ... Q33: =Q14*AG33 -> 4125.9352 | R33: =RATE(9,,-H33,Q33) -> 0.13578671 | S33: Breast cancer | T33: 0.18 | U33: 0.18015306 | V33: 0.18030626 | W33: 0.18045958 | X33: 0.18061303 | Y33: 0.18076662 | Z33: 0.18092033 | AA33: 0.18107418 | AB33: 0.18122815 | AC33: 0.18138226 | AD33: 0.1815365 | AE33: 0.18169087 | AF33: 0.18184537 | AG33: 0.182
B34: Prostate cancer | D34: =D14*T34 -> 550.68 | E34: =E14*U34 -> 617.21957 | F34: =F14*V34 -> 692.9956 | G34: =G14*W34 -> 779.42888 | H34: =H14*X34 -> 878.17926 | I34: =I14*Y34 -> 991.18938 | J34: =J14*Z34 -> 1120.7371 | K34: =K14*AA34 -> 1269.4984 | ... Q34: =Q14*AG34 -> 2788.4067 | R34: =RATE(9,,-H34,Q34) -> 0.13697928 | S34: Prostate cancer | T34: 0.12 | U34: 0.12022815 | V34: 0.12045673 | W34: 0.12068575 | X34: 0.1209152 | Y34: 0.12114509 | Z34: 0.12137541 | AA34: 0.12160618 | AB34: 0.12183738 | AC34: 0.12206902 | AD34: 0.1223011 | AE34: 0.12253363 | AF34: 0.12276659 | AG34: 0.123
B35: Liver cancer | D35: =D14*T35 -> 458.9 | E35: =E14*U35 -> 515.30395 | F35: =F14*V35 -> 579.64127 | G35: =G14*W35 -> 653.14611 | H35: =H14*X35 -> 737.26236 | I35: =I14*Y35 -> 833.68226 | J35: =J14*Z35 -> 944.39287 | K35: =K14*AA35 -> 1071.7318 | ... Q35: =Q14*AG35 -> 2380.3472 | R35: =RATE(9,,-H35,Q35) -> 0.1390888 | S35: Liver cancer | T35: 0.1 | U35: 0.10037601 | V35: 0.10075344 | W35: 0.10113229 | X35: 0.10151256 | Y35: 0.10189426 | Z35: 0.1022774 | AA35: 0.10266198 | AB35: 0.103048 | AC35: 0.10343548 | AD35: 0.10382441 | AE35: 0.1042148 | AF35: 0.10460666 | AG35: 0.105
B36: Head & neck cancer | D36: =D14*T36 -> 596.57 | E36: =E14*U36 -> 668.94329 | F36: =F14*V36 -> 751.39378 | G36: =G14*W36 -> 845.47567 | H36: =H14*X36 -> 953.00528 | I36: =I14*Y36 -> 1076.109 | J36: =J14*Z36 -> 1217.2811 | K36: =K14*AA36 -> 1379.4526 | ... Q36: =Q14*AG36 -> 3037.7764 | R36: =RATE(9,,-H36,Q36) -> 0.13747027 | S36: Head & neck cancer | T36: 0.13 | U36: 0.13030341 | V36: 0.13060752 | W36: 0.13091235 | X36: 0.13121788 | Y36: 0.13152413 | Z36: 0.1318311 | AA36: 0.13213878 | AB36: 0.13244718 | AC36: 0.13275629 | AD36: 0.13306613 | AE36: 0.1333767 | AF36: 0.13368799 | AG36: 0.134
B37: Others cancers | D37: =D14*T37 -> 91.78 | E37: =E14*U37 -> 104.06046 | F37: =F14*V37 -> 117.97819 | G37: =G14*W37 -> 133.76136 | H37: =H14*X37 -> 151.67127 | I37: =I14*Y37 -> 172.00734 | J37: =J14*Z37 -> 195.11288 | K37: =K14*AA37 -> 221.38176 | ... Q37: =Q14*AG37 -> 476.06944 | R37: =RATE(9,,-H37,Q37) -> 0.13552403 | S37: Others cancers | T37: =1-SUM(T31:T36) -> 0.02 | U37: =1-SUM(U31:U36) -> 0.020269928 | V37: =1-SUM(V31:V36) -> 0.020507009 | W37: =1-SUM(W31:W36) -> 0.020711434 | X37: =1-SUM(X31:X36) -> 0.020883393 | Y37: =1-SUM(Y31:Y36) -> 0.021023071 | Z37: =1-SUM(Z31:Z36) -> 0.021130653 | AA37: =1-SUM(AA31:AA36) -> 0.021206321 | ... AG37: =1-SUM(AG31:AG36) -> 0.021
D38: =D14=SUM(D31:D37) -> TRUE | E38: =E14=SUM(E31:E37) -> TRUE | F38: =F14=SUM(F31:F37) -> TRUE | G38: =G14=SUM(G31:G37) -> TRUE | H38: =H14=SUM(H31:H37) -> TRUE | I38: =I14=SUM(I31:I37) -> TRUE | J38: =J14=SUM(J31:J37) -> FALSE | K38: =K14=SUM(K31:K37) -> TRUE | ... Q38: =Q14=SUM(Q31:Q37) -> TRUE

Sheet Dashboard
A2: Dynamic Dashboard Liquid Biopsy Market, 2027-36 (USD Million)
A3: 5
R5: CAGR%(2027-2036) | S5: {=_xlfn.IFS($A$3=1,Global!R14,$A$3=2,'North America'!R14,$A$3=3,APAC!R14,$A$3=4,Europe!R14,$A$3=5,'Latin America'!R14,$A$3=6,MEA!R14)} -> 0.13436227
D25: 2023 | E25: 2024 | F25: 2025 | G25: 2026 | H25: 2027 | I25: 2028 | J25: 2029 | K25: 2030 | L25: 2031 | M25: 2032 | N25: 2033 | O25: 2034 | P25: 2035 | Q25: 2036 | R25: CAGR (2027-2036)
D26: {=_xlfn.IFS($A$3=1,Global!D14,$A$3=2,'North America'!D14,$A$3=3,APAC!D14,$A$3=4,Europe!D14,$A$3=5,'Latin America'!D14,$A$3=6,MEA!D14)} -> 977.457 | E26: {=_xlfn.IFS($A$3=1,Global!E14,$A$3=2,'North America'!E14,$A$3=3,APAC!E14,$A$3=4,Europe!E14,$A$3=5,'Latin America'!E14,$A$3=6,MEA!E14)} -> 1097.2402 | F26: {=_xlfn.IFS($A$3=1,Global!F14,$A$3=2,'North America'!F14,$A$3=3,APAC!F14,$A$3=4,Europe!F14,$A$3=5,'Latin America'!F14,$A$3=6,MEA!F14)} -> 1233.1111 | G26: {=_xlfn.IFS($A$3=1,Global!G14,$A$3=2,'North America'!G14,$A$3=3,APAC!G14,$A$3=4,Europe!G14,$A$3=5,'Latin America'!G14,$A$3=6,MEA!G14)} -> 1387.4368 | H26: {=_xlfn.IFS($A$3=1,Global!H14,$A$3=2,'North America'!H14,$A$3=3,APAC!H14,$A$3=4,Europe!H14,$A$3=5,'Latin America'!H14,$A$3=6,MEA!H14)} -> 1562.9683 | I26: {=_xlfn.IFS($A$3=1,Global!I14,$A$3=2,'North America'!I14,$A$3=3,APAC!I14,$A$3=4,Europe!I14,$A$3=5,'Latin America'!I14,$A$3=6,MEA!I14)} -> 1762.9101 | J26: {=_xlfn.IFS($A$3=1,Global!J14,$A$3=2,'North America'!J14,$A$3=3,APAC!J14,$A$3=4,Europe!J14,$A$3=5,'Latin America'!J14,$A$3=6,MEA!J14)} -> 1991.0027 | K26: {=_xlfn.IFS($A$3=1,Global!K14,$A$3=2,'North America'!K14,$A$3=3,APAC!K14,$A$3=4,Europe!K14,$A$3=5,'Latin America'!K14,$A$3=6,MEA!K14)} -> 2251.6241 | ... Q26: {=_xlfn.IFS($A$3=1,Global!Q14,$A$3=2,'North America'!Q14,$A$3=3,APAC!Q14,$A$3=4,Europe!Q14,$A$3=5,'Latin America'!Q14,$A$3=6,MEA!Q14)} -> 4860.8939 | R26: =RATE(9,,-H26,Q26) -> 0.13436227
A27: Biomarker Type | B27: Circulating tumor cells | D27: {=_xlfn.IFS($A$3=1,Global!D15,$A$3=2,'North America'!D15,$A$3=3,APAC!D15,$A$3=4,Europe!D15,$A$3=5,'Latin America'!D15,$A$3=6,MEA!D15)} -> 293.2371 | E27: {=_xlfn.IFS($A$3=1,Global!E15,$A$3=2,'North America'!E15,$A$3=3,APAC!E15,$A$3=4,Europe!E15,$A$3=5,'Latin America'!E15,$A$3=6,MEA!E15)} -> 333.09854 | F27: {=_xlfn.IFS($A$3=1,Global!F15,$A$3=2,'North America'!F15,$A$3=3,APAC!F15,$A$3=4,Europe!F15,$A$3=5,'Latin America'!F15,$A$3=6,MEA!F15)} -> 378.81134 | G27: {=_xlfn.IFS($A$3=1,Global!G15,$A$3=2,'North America'!G15,$A$3=3,APAC!G15,$A$3=4,Europe!G15,$A$3=5,'Latin America'!G15,$A$3=6,MEA!G15)} -> 431.30423 | H27: {=_xlfn.IFS($A$3=1,Global!H15,$A$3=2,'North America'!H15,$A$3=3,APAC!H15,$A$3=4,Europe!H15,$A$3=5,'Latin America'!H15,$A$3=6,MEA!H15)} -> 491.66631 | I27: {=_xlfn.IFS($A$3=1,Global!I15,$A$3=2,'North America'!I15,$A$3=3,APAC!I15,$A$3=4,Europe!I15,$A$3=5,'Latin America'!I15,$A$3=6,MEA!I15)} -> 561.1774 | J27: {=_xlfn.IFS($A$3=1,Global!J15,$A$3=2,'North America'!J15,$A$3=3,APAC!J15,$A$3=4,Europe!J15,$A$3=5,'Latin America'!J15,$A$3=6,MEA!J15)} -> 641.34487 | K27: {=_xlfn.IFS($A$3=1,Global!K15,$A$3=2,'North America'!K15,$A$3=3,APAC!K15,$A$3=4,Europe!K15,$A$3=5,'Latin America'!K15,$A$3=6,MEA!K15)} -> 733.94822 | ... Q27: {=_xlfn.IFS($A$3=1,Global!Q15,$A$3=2,'North America'!Q15,$A$3=3,APAC!Q15,$A$3=4,Europe!Q15,$A$3=5,'Latin America'!Q15,$A$3=6,MEA!Q15)} -> 1701.3129 | R27: =RATE(9,,-H27,Q27) -> 0.14789331
B28: Circulating tumor DNA | D28: {=_xlfn.IFS($A$3=1,Global!D16,$A$3=2,'North America'!D16,$A$3=3,APAC!D16,$A$3=4,Europe!D16,$A$3=5,'Latin America'!D16,$A$3=6,MEA!D16)} -> 195.4914 | E28: {=_xlfn.IFS($A$3=1,Global!E16,$A$3=2,'North America'!E16,$A$3=3,APAC!E16,$A$3=4,Europe!E16,$A$3=5,'Latin America'!E16,$A$3=6,MEA!E16)} -> 220.2732 | F28: {=_xlfn.IFS($A$3=1,Global!F16,$A$3=2,'North America'!F16,$A$3=3,APAC!F16,$A$3=4,Europe!F16,$A$3=5,'Latin America'!F16,$A$3=6,MEA!F16)} -> 248.48038 | G28: {=_xlfn.IFS($A$3=1,Global!G16,$A$3=2,'North America'!G16,$A$3=3,APAC!G16,$A$3=4,Europe!G16,$A$3=5,'Latin America'!G16,$A$3=6,MEA!G16)} -> 280.62932 | H28: {=_xlfn.IFS($A$3=1,Global!H16,$A$3=2,'North America'!H16,$A$3=3,APAC!H16,$A$3=4,Europe!H16,$A$3=5,'Latin America'!H16,$A$3=6,MEA!H16)} -> 317.32184 | I28: {=_xlfn.IFS($A$3=1,Global!I16,$A$3=2,'North America'!I16,$A$3=3,APAC!I16,$A$3=4,Europe!I16,$A$3=5,'Latin America'!I16,$A$3=6,MEA!I16)} -> 359.26084 | J28: {=_xlfn.IFS($A$3=1,Global!J16,$A$3=2,'North America'!J16,$A$3=3,APAC!J16,$A$3=4,Europe!J16,$A$3=5,'Latin America'!J16,$A$3=6,MEA!J16)} -> 407.26916 | K28: {=_xlfn.IFS($A$3=1,Global!K16,$A$3=2,'North America'!K16,$A$3=3,APAC!K16,$A$3=4,Europe!K16,$A$3=5,'Latin America'!K16,$A$3=6,MEA!K16)} -> 462.31237 | ... Q28: {=_xlfn.IFS($A$3=1,Global!Q16,$A$3=2,'North America'!Q16,$A$3=3,APAC!Q16,$A$3=4,Europe!Q16,$A$3=5,'Latin America'!Q16,$A$3=6,MEA!Q16)} -> 1020.7877 | R28: =RATE(9,,-H28,Q28) -> 0.13862763
B29: Exosomes | D29: {=_xlfn.IFS($A$3=1,Global!D17,$A$3=2,'North America'!D17,$A$3=3,APAC!D17,$A$3=4,Europe!D17,$A$3=5,'Latin America'!D17,$A$3=6,MEA!D17)} -> 97.7457 | E29: {=_xlfn.IFS($A$3=1,Global!E17,$A$3=2,'North America'!E17,$A$3=3,APAC!E17,$A$3=4,Europe!E17,$A$3=5,'Latin America'!E17,$A$3=6,MEA!E17)} -> 111.27371 | F29: {=_xlfn.IFS($A$3=1,Global!F17,$A$3=2,'North America'!F17,$A$3=3,APAC!F17,$A$3=4,Europe!F17,$A$3=5,'Latin America'!F17,$A$3=6,MEA!F17)} -> 126.81889 | G29: {=_xlfn.IFS($A$3=1,Global!G17,$A$3=2,'North America'!G17,$A$3=3,APAC!G17,$A$3=4,Europe!G17,$A$3=5,'Latin America'!G17,$A$3=6,MEA!G17)} -> 144.70575 | H29: {=_xlfn.IFS($A$3=1,Global!H17,$A$3=2,'North America'!H17,$A$3=3,APAC!H17,$A$3=4,Europe!H17,$A$3=5,'Latin America'!H17,$A$3=6,MEA!H17)} -> 165.31553 | I29: {=_xlfn.IFS($A$3=1,Global!I17,$A$3=2,'North America'!I17,$A$3=3,APAC!I17,$A$3=4,Europe!I17,$A$3=5,'Latin America'!I17,$A$3=6,MEA!I17)} -> 189.09693 | J29: {=_xlfn.IFS($A$3=1,Global!J17,$A$3=2,'North America'!J17,$A$3=3,APAC!J17,$A$3=4,Europe!J17,$A$3=5,'Latin America'!J17,$A$3=6,MEA!J17)} -> 216.57935 | K29: {=_xlfn.IFS($A$3=1,Global!K17,$A$3=2,'North America'!K17,$A$3=3,APAC!K17,$A$3=4,Europe!K17,$A$3=5,'Latin America'!K17,$A$3=6,MEA!K17)} -> 248.38877 | ... Q29: {=_xlfn.IFS($A$3=1,Global!Q17,$A$3=2,'North America'!Q17,$A$3=3,APAC!Q17,$A$3=4,Europe!Q17,$A$3=5,'Latin America'!Q17,$A$3=6,MEA!Q17)} -> 583.30727 | R29: =RATE(9,,-H29,Q29) -> 0.15038349
B30: Circulating RNA & proteins | D30: {=_xlfn.IFS($A$3=1,Global!D18,$A$3=2,'North America'!D18,$A$3=3,APAC!D18,$A$3=4,Europe!D18,$A$3=5,'Latin America'!D18,$A$3=6,MEA!D18)} -> 68.42199 | E30: {=_xlfn.IFS($A$3=1,Global!E18,$A$3=2,'North America'!E18,$A$3=3,APAC!E18,$A$3=4,Europe!E18,$A$3=5,'Latin America'!E18,$A$3=6,MEA!E18)} -> 77.215524 | F30: {=_xlfn.IFS($A$3=1,Global!F18,$A$3=2,'North America'!F18,$A$3=3,APAC!F18,$A$3=4,Europe!F18,$A$3=5,'Latin America'!F18,$A$3=6,MEA!F18)} -> 87.238859 | G30: {=_xlfn.IFS($A$3=1,Global!G18,$A$3=2,'North America'!G18,$A$3=3,APAC!G18,$A$3=4,Europe!G18,$A$3=5,'Latin America'!G18,$A$3=6,MEA!G18)} -> 98.679249 | H30: {=_xlfn.IFS($A$3=1,Global!H18,$A$3=2,'North America'!H18,$A$3=3,APAC!H18,$A$3=4,Europe!H18,$A$3=5,'Latin America'!H18,$A$3=6,MEA!H18)} -> 111.75518 | I30: {=_xlfn.IFS($A$3=1,Global!I18,$A$3=2,'North America'!I18,$A$3=3,APAC!I18,$A$3=4,Europe!I18,$A$3=5,'Latin America'!I18,$A$3=6,MEA!I18)} -> 126.72214 | J30: {=_xlfn.IFS($A$3=1,Global!J18,$A$3=2,'North America'!J18,$A$3=3,APAC!J18,$A$3=4,Europe!J18,$A$3=5,'Latin America'!J18,$A$3=6,MEA!J18)} -> 143.87955 | K30: {=_xlfn.IFS($A$3=1,Global!K18,$A$3=2,'North America'!K18,$A$3=3,APAC!K18,$A$3=4,Europe!K18,$A$3=5,'Latin America'!K18,$A$3=6,MEA!K18)} -> 163.57916 | ... Q30: {=_xlfn.IFS($A$3=1,Global!Q18,$A$3=2,'North America'!Q18,$A$3=3,APAC!Q18,$A$3=4,Europe!Q18,$A$3=5,'Latin America'!Q18,$A$3=6,MEA!Q18)} -> 364.56704 | R30: =RATE(9,,-H30,Q30) -> 0.1403985
B31: Nucleosomes | D31: {=_xlfn.IFS($A$3=1,Global!D19,$A$3=2,'North America'!D19,$A$3=3,APAC!D19,$A$3=4,Europe!D19,$A$3=5,'Latin America'!D19,$A$3=6,MEA!D19)} -> 322.56081 | E31: {=_xlfn.IFS($A$3=1,Global!E19,$A$3=2,'North America'!E19,$A$3=3,APAC!E19,$A$3=4,Europe!E19,$A$3=5,'Latin America'!E19,$A$3=6,MEA!E19)} -> 355.37925 | F31: {=_xlfn.IFS($A$3=1,Global!F19,$A$3=2,'North America'!F19,$A$3=3,APAC!F19,$A$3=4,Europe!F19,$A$3=5,'Latin America'!F19,$A$3=6,MEA!F19)} -> 391.76165 | G31: {=_xlfn.IFS($A$3=1,Global!G19,$A$3=2,'North America'!G19,$A$3=3,APAC!G19,$A$3=4,Europe!G19,$A$3=5,'Latin America'!G19,$A$3=6,MEA!G19)} -> 432.11824 | H31: {=_xlfn.IFS($A$3=1,Global!H19,$A$3=2,'North America'!H19,$A$3=3,APAC!H19,$A$3=4,Europe!H19,$A$3=5,'Latin America'!H19,$A$3=6,MEA!H19)} -> 476.90949 | I31: {=_xlfn.IFS($A$3=1,Global!I19,$A$3=2,'North America'!I19,$A$3=3,APAC!I19,$A$3=4,Europe!I19,$A$3=5,'Latin America'!I19,$A$3=6,MEA!I19)} -> 526.65274 | J31: {=_xlfn.IFS($A$3=1,Global!J19,$A$3=2,'North America'!J19,$A$3=3,APAC!J19,$A$3=4,Europe!J19,$A$3=5,'Latin America'!J19,$A$3=6,MEA!J19)} -> 581.92979 | K31: {=_xlfn.IFS($A$3=1,Global!K19,$A$3=2,'North America'!K19,$A$3=3,APAC!K19,$A$3=4,Europe!K19,$A$3=5,'Latin America'!K19,$A$3=6,MEA!K19)} -> 643.39562 | ... Q31: {=_xlfn.IFS($A$3=1,Global!Q19,$A$3=2,'North America'!Q19,$A$3=3,APAC!Q19,$A$3=4,Europe!Q19,$A$3=5,'Latin America'!Q19,$A$3=6,MEA!Q19)} -> 1190.919 | R31: =RATE(9,,-H31,Q31) -> 0.10703333
A33: Sample | B33: Blood | D33: {=_xlfn.IFS($A$3=1,Global!D21,$A$3=2,'North America'!D21,$A$3=3,APAC!D21,$A$3=4,Europe!D21,$A$3=5,'Latin America'!D21,$A$3=6,MEA!D21)} -> 684.2199 | E33: {=_xlfn.IFS($A$3=1,Global!E21,$A$3=2,'North America'!E21,$A$3=3,APAC!E21,$A$3=4,Europe!E21,$A$3=5,'Latin America'!E21,$A$3=6,MEA!E21)} -> 768.15256 | F33: {=_xlfn.IFS($A$3=1,Global!F21,$A$3=2,'North America'!F21,$A$3=3,APAC!F21,$A$3=4,Europe!F21,$A$3=5,'Latin America'!F21,$A$3=6,MEA!F21)} -> 863.36749 | G33: {=_xlfn.IFS($A$3=1,Global!G21,$A$3=2,'North America'!G21,$A$3=3,APAC!G21,$A$3=4,Europe!G21,$A$3=5,'Latin America'!G21,$A$3=6,MEA!G21)} -> 971.52593 | H33: {=_xlfn.IFS($A$3=1,Global!H21,$A$3=2,'North America'!H21,$A$3=3,APAC!H21,$A$3=4,Europe!H21,$A$3=5,'Latin America'!H21,$A$3=6,MEA!H21)} -> 1094.5588 | I33: {=_xlfn.IFS($A$3=1,Global!I21,$A$3=2,'North America'!I21,$A$3=3,APAC!I21,$A$3=4,Europe!I21,$A$3=5,'Latin America'!I21,$A$3=6,MEA!I21)} -> 1234.7151 | J33: {=_xlfn.IFS($A$3=1,Global!J21,$A$3=2,'North America'!J21,$A$3=3,APAC!J21,$A$3=4,Europe!J21,$A$3=5,'Latin America'!J21,$A$3=6,MEA!J21)} -> 1394.6208 | K33: {=_xlfn.IFS($A$3=1,Global!K21,$A$3=2,'North America'!K21,$A$3=3,APAC!K21,$A$3=4,Europe!K21,$A$3=5,'Latin America'!K21,$A$3=6,MEA!K21)} -> 1577.3493 | ... Q33: {=_xlfn.IFS($A$3=1,Global!Q21,$A$3=2,'North America'!Q21,$A$3=3,APAC!Q21,$A$3=4,Europe!Q21,$A$3=5,'Latin America'!Q21,$A$3=6,MEA!Q21)} -> 3407.4866 | R33: =RATE(9,,-H33,Q33) -> 0.13448682
B34: Urine | D34: {=_xlfn.IFS($A$3=1,Global!D22,$A$3=2,'North America'!D22,$A$3=3,APAC!D22,$A$3=4,Europe!D22,$A$3=5,'Latin America'!D22,$A$3=6,MEA!D22)} -> 195.4914 | E34: {=_xlfn.IFS($A$3=1,Global!E22,$A$3=2,'North America'!E22,$A$3=3,APAC!E22,$A$3=4,Europe!E22,$A$3=5,'Latin America'!E22,$A$3=6,MEA!E22)} -> 219.53245 | F34: {=_xlfn.IFS($A$3=1,Global!F22,$A$3=2,'North America'!F22,$A$3=3,APAC!F22,$A$3=4,Europe!F22,$A$3=5,'Latin America'!F22,$A$3=6,MEA!F22)} -> 246.81193 | G34: {=_xlfn.IFS($A$3=1,Global!G22,$A$3=2,'North America'!G22,$A$3=3,APAC!G22,$A$3=4,Europe!G22,$A$3=5,'Latin America'!G22,$A$3=6,MEA!G22)} -> 277.80754 | H34: {=_xlfn.IFS($A$3=1,Global!H22,$A$3=2,'North America'!H22,$A$3=3,APAC!H22,$A$3=4,Europe!H22,$A$3=5,'Latin America'!H22,$A$3=6,MEA!H22)} -> 313.07458 | I34: {=_xlfn.IFS($A$3=1,Global!I22,$A$3=2,'North America'!I22,$A$3=3,APAC!I22,$A$3=4,Europe!I22,$A$3=5,'Latin America'!I22,$A$3=6,MEA!I22)} -> 353.26005 | J34: {=_xlfn.IFS($A$3=1,Global!J22,$A$3=2,'North America'!J22,$A$3=3,APAC!J22,$A$3=4,Europe!J22,$A$3=5,'Latin America'!J22,$A$3=6,MEA!J22)} -> 399.11947 | K34: {=_xlfn.IFS($A$3=1,Global!K22,$A$3=2,'North America'!K22,$A$3=3,APAC!K22,$A$3=4,Europe!K22,$A$3=5,'Latin America'!K22,$A$3=6,MEA!K22)} -> 451.53724 | ... Q34: {=_xlfn.IFS($A$3=1,Global!Q22,$A$3=2,'North America'!Q22,$A$3=3,APAC!Q22,$A$3=4,Europe!Q22,$A$3=5,'Latin America'!Q22,$A$3=6,MEA!Q22)} -> 977.03967 | R34: =RATE(9,,-H34,Q34) -> 0.13479723
B35: Others (Serum) | D35: {=_xlfn.IFS($A$3=1,Global!D23,$A$3=2,'North America'!D23,$A$3=3,APAC!D23,$A$3=4,Europe!D23,$A$3=5,'Latin America'!D23,$A$3=6,MEA!D23)} -> 97.7457 | E35: {=_xlfn.IFS($A$3=1,Global!E23,$A$3=2,'North America'!E23,$A$3=3,APAC!E23,$A$3=4,Europe!E23,$A$3=5,'Latin America'!E23,$A$3=6,MEA!E23)} -> 109.55522 | F35: {=_xlfn.IFS($A$3=1,Global!F23,$A$3=2,'North America'!F23,$A$3=3,APAC!F23,$A$3=4,Europe!F23,$A$3=5,'Latin America'!F23,$A$3=6,MEA!F23)} -> 122.93169 | G35: {=_xlfn.IFS($A$3=1,Global!G23,$A$3=2,'North America'!G23,$A$3=3,APAC!G23,$A$3=4,Europe!G23,$A$3=5,'Latin America'!G23,$A$3=6,MEA!G23)} -> 138.10332 | H35: {=_xlfn.IFS($A$3=1,Global!H23,$A$3=2,'North America'!H23,$A$3=3,APAC!H23,$A$3=4,Europe!H23,$A$3=5,'Latin America'!H23,$A$3=6,MEA!H23)} -> 155.33501 | I35: {=_xlfn.IFS($A$3=1,Global!I23,$A$3=2,'North America'!I23,$A$3=3,APAC!I23,$A$3=4,Europe!I23,$A$3=5,'Latin America'!I23,$A$3=6,MEA!I23)} -> 174.93492 | J35: {=_xlfn.IFS($A$3=1,Global!J23,$A$3=2,'North America'!J23,$A$3=3,APAC!J23,$A$3=4,Europe!J23,$A$3=5,'Latin America'!J23,$A$3=6,MEA!J23)} -> 197.26242 | K35: {=_xlfn.IFS($A$3=1,Global!K23,$A$3=2,'North America'!K23,$A$3=3,APAC!K23,$A$3=4,Europe!K23,$A$3=5,'Latin America'!K23,$A$3=6,MEA!K23)} -> 222.73759 | ... Q35: {=_xlfn.IFS($A$3=1,Global!Q23,$A$3=2,'North America'!Q23,$A$3=3,APAC!Q23,$A$3=4,Europe!Q23,$A$3=5,'Latin America'!Q23,$A$3=6,MEA!Q23)} -> 476.3676 | R35: =RATE(9,,-H35,Q35) -> 0.13259532
A37: Clinical Application | B37: Early disease screening | D37: {=_xlfn.IFS($A$3=1,Global!D25,$A$3=2,'North America'!D25,$A$3=3,APAC!D25,$A$3=4,Europe!D25,$A$3=5,'Latin America'!D25,$A$3=6,MEA!D25)} -> 293.2371 | E37: {=_xlfn.IFS($A$3=1,Global!E25,$A$3=2,'North America'!E25,$A$3=3,APAC!E25,$A$3=4,Europe!E25,$A$3=5,'Latin America'!E25,$A$3=6,MEA!E25)} -> 331.8252 | F37: {=_xlfn.IFS($A$3=1,Global!F25,$A$3=2,'North America'!F25,$A$3=3,APAC!F25,$A$3=4,Europe!F25,$A$3=5,'Latin America'!F25,$A$3=6,MEA!F25)} -> 375.92069 | G37: {=_xlfn.IFS($A$3=1,Global!G25,$A$3=2,'North America'!G25,$A$3=3,APAC!G25,$A$3=4,Europe!G25,$A$3=5,'Latin America'!G25,$A$3=6,MEA!G25)} -> 426.37684 | H37: {=_xlfn.IFS($A$3=1,Global!H25,$A$3=2,'North America'!H25,$A$3=3,APAC!H25,$A$3=4,Europe!H25,$A$3=5,'Latin America'!H25,$A$3=6,MEA!H25)} -> 484.19128 | I37: {=_xlfn.IFS($A$3=1,Global!I25,$A$3=2,'North America'!I25,$A$3=3,APAC!I25,$A$3=4,Europe!I25,$A$3=5,'Latin America'!I25,$A$3=6,MEA!I25)} -> 550.53296 | J37: {=_xlfn.IFS($A$3=1,Global!J25,$A$3=2,'North America'!J25,$A$3=3,APAC!J25,$A$3=4,Europe!J25,$A$3=5,'Latin America'!J25,$A$3=6,MEA!J25)} -> 626.77463 | K37: {=_xlfn.IFS($A$3=1,Global!K25,$A$3=2,'North America'!K25,$A$3=3,APAC!K25,$A$3=4,Europe!K25,$A$3=5,'Latin America'!K25,$A$3=6,MEA!K25)} -> 714.53224 | ... Q37: {=_xlfn.IFS($A$3=1,Global!Q25,$A$3=2,'North America'!Q25,$A$3=3,APAC!Q25,$A$3=4,Europe!Q25,$A$3=5,'Latin America'!Q25,$A$3=6,MEA!Q25)} -> 1618.6777 | R37: =RATE(9,,-H37,Q37) -> 0.14350523
B38: Therapy selection | D38: {=_xlfn.IFS($A$3=1,Global!D26,$A$3=2,'North America'!D26,$A$3=3,APAC!D26,$A$3=4,Europe!D26,$A$3=5,'Latin America'!D26,$A$3=6,MEA!D26)} -> 195.4914 | E38: {=_xlfn.IFS($A$3=1,Global!E26,$A$3=2,'North America'!E26,$A$3=3,APAC!E26,$A$3=4,Europe!E26,$A$3=5,'Latin America'!E26,$A$3=6,MEA!E26)} -> 221.06285 | F38: {=_xlfn.IFS($A$3=1,Global!F26,$A$3=2,'North America'!F26,$A$3=3,APAC!F26,$A$3=4,Europe!F26,$A$3=5,'Latin America'!F26,$A$3=6,MEA!F26)} -> 250.26511 | G38: {=_xlfn.IFS($A$3=1,Global!G26,$A$3=2,'North America'!G26,$A$3=3,APAC!G26,$A$3=4,Europe!G26,$A$3=5,'Latin America'!G26,$A$3=6,MEA!G26)} -> 283.65821 | H38: {=_xlfn.IFS($A$3=1,Global!H26,$A$3=2,'North America'!H26,$A$3=3,APAC!H26,$A$3=4,Europe!H26,$A$3=5,'Latin America'!H26,$A$3=6,MEA!H26)} -> 321.8966 | I38: {=_xlfn.IFS($A$3=1,Global!I26,$A$3=2,'North America'!I26,$A$3=3,APAC!I26,$A$3=4,Europe!I26,$A$3=5,'Latin America'!I26,$A$3=6,MEA!I26)} -> 365.7467 | J38: {=_xlfn.IFS($A$3=1,Global!J26,$A$3=2,'North America'!J26,$A$3=3,APAC!J26,$A$3=4,Europe!J26,$A$3=5,'Latin America'!J26,$A$3=6,MEA!J26)} -> 416.1081 | K38: {=_xlfn.IFS($A$3=1,Global!K26,$A$3=2,'North America'!K26,$A$3=3,APAC!K26,$A$3=4,Europe!K26,$A$3=5,'Latin America'!K26,$A$3=6,MEA!K26)} -> 474.0392 | ... Q38: {=_xlfn.IFS($A$3=1,Global!Q26,$A$3=2,'North America'!Q26,$A$3=3,APAC!Q26,$A$3=4,Europe!Q26,$A$3=5,'Latin America'!Q26,$A$3=6,MEA!Q26)} -> 1069.3967 | R38: =RATE(9,,-H38,Q38) -> 0.14270947
B39: Treatment response monitoring | D39: {=_xlfn.IFS($A$3=1,Global!D27,$A$3=2,'North America'!D27,$A$3=3,APAC!D27,$A$3=4,Europe!D27,$A$3=5,'Latin America'!D27,$A$3=6,MEA!D27)} -> 146.61855 | E39: {=_xlfn.IFS($A$3=1,Global!E27,$A$3=2,'North America'!E27,$A$3=3,APAC!E27,$A$3=4,Europe!E27,$A$3=5,'Latin America'!E27,$A$3=6,MEA!E27)} -> 165.79714 | F39: {=_xlfn.IFS($A$3=1,Global!F27,$A$3=2,'North America'!F27,$A$3=3,APAC!F27,$A$3=4,Europe!F27,$A$3=5,'Latin America'!F27,$A$3=6,MEA!F27)} -> 187.69883 | G39: {=_xlfn.IFS($A$3=1,Global!G27,$A$3=2,'North America'!G27,$A$3=3,APAC!G27,$A$3=4,Europe!G27,$A$3=5,'Latin America'!G27,$A$3=6,MEA!G27)} -> 212.74366 | H39: {=_xlfn.IFS($A$3=1,Global!H27,$A$3=2,'North America'!H27,$A$3=3,APAC!H27,$A$3=4,Europe!H27,$A$3=5,'Latin America'!H27,$A$3=6,MEA!H27)} -> 241.42245 | I39: {=_xlfn.IFS($A$3=1,Global!I27,$A$3=2,'North America'!I27,$A$3=3,APAC!I27,$A$3=4,Europe!I27,$A$3=5,'Latin America'!I27,$A$3=6,MEA!I27)} -> 274.31002 | J39: {=_xlfn.IFS($A$3=1,Global!J27,$A$3=2,'North America'!J27,$A$3=3,APAC!J27,$A$3=4,Europe!J27,$A$3=5,'Latin America'!J27,$A$3=6,MEA!J27)} -> 312.08107 | K39: {=_xlfn.IFS($A$3=1,Global!K27,$A$3=2,'North America'!K27,$A$3=3,APAC!K27,$A$3=4,Europe!K27,$A$3=5,'Latin America'!K27,$A$3=6,MEA!K27)} -> 355.5294 | ... Q39: {=_xlfn.IFS($A$3=1,Global!Q27,$A$3=2,'North America'!Q27,$A$3=3,APAC!Q27,$A$3=4,Europe!Q27,$A$3=5,'Latin America'!Q27,$A$3=6,MEA!Q27)} -> 802.04749 | R39: =RATE(9,,-H39,Q39) -> 0.14270947
B40: Molecular health monitoring | D40: {=_xlfn.IFS($A$3=1,Global!D28,$A$3=2,'North America'!D28,$A$3=3,APAC!D28,$A$3=4,Europe!D28,$A$3=5,'Latin America'!D28,$A$3=6,MEA!D28)} -> 68.42199 | E40: {=_xlfn.IFS($A$3=1,Global!E28,$A$3=2,'North America'!E28,$A$3=3,APAC!E28,$A$3=4,Europe!E28,$A$3=5,'Latin America'!E28,$A$3=6,MEA!E28)} -> 77.215524 | F40: {=_xlfn.IFS($A$3=1,Global!F28,$A$3=2,'North America'!F28,$A$3=3,APAC!F28,$A$3=4,Europe!F28,$A$3=5,'Latin America'!F28,$A$3=6,MEA!F28)} -> 87.238859 | G40: {=_xlfn.IFS($A$3=1,Global!G28,$A$3=2,'North America'!G28,$A$3=3,APAC!G28,$A$3=4,Europe!G28,$A$3=5,'Latin America'!G28,$A$3=6,MEA!G28)} -> 98.679249 | H40: {=_xlfn.IFS($A$3=1,Global!H28,$A$3=2,'North America'!H28,$A$3=3,APAC!H28,$A$3=4,Europe!H28,$A$3=5,'Latin America'!H28,$A$3=6,MEA!H28)} -> 111.75518 | I40: {=_xlfn.IFS($A$3=1,Global!I28,$A$3=2,'North America'!I28,$A$3=3,APAC!I28,$A$3=4,Europe!I28,$A$3=5,'Latin America'!I28,$A$3=6,MEA!I28)} -> 126.72214 | J40: {=_xlfn.IFS($A$3=1,Global!J28,$A$3=2,'North America'!J28,$A$3=3,APAC!J28,$A$3=4,Europe!J28,$A$3=5,'Latin America'!J28,$A$3=6,MEA!J28)} -> 143.87955 | K40: {=_xlfn.IFS($A$3=1,Global!K28,$A$3=2,'North America'!K28,$A$3=3,APAC!K28,$A$3=4,Europe!K28,$A$3=5,'Latin America'!K28,$A$3=6,MEA!K28)} -> 163.57916 | ... Q40: {=_xlfn.IFS($A$3=1,Global!Q28,$A$3=2,'North America'!Q28,$A$3=3,APAC!Q28,$A$3=4,Europe!Q28,$A$3=5,'Latin America'!Q28,$A$3=6,MEA!Q28)} -> 364.56704 | R40: =RATE(9,,-H40,Q40) -> 0.1403985
B41: Others | D41: {=_xlfn.IFS($A$3=1,Global!D29,$A$3=2,'North America'!D29,$A$3=3,APAC!D29,$A$3=4,Europe!D29,$A$3=5,'Latin America'!D29,$A$3=6,MEA!D29)} -> 273.68796 | E41: {=_xlfn.IFS($A$3=1,Global!E29,$A$3=2,'North America'!E29,$A$3=3,APAC!E29,$A$3=4,Europe!E29,$A$3=5,'Latin America'!E29,$A$3=6,MEA!E29)} -> 301.33951 | F41: {=_xlfn.IFS($A$3=1,Global!F29,$A$3=2,'North America'!F29,$A$3=3,APAC!F29,$A$3=4,Europe!F29,$A$3=5,'Latin America'!F29,$A$3=6,MEA!F29)} -> 331.98761 | G41: {=_xlfn.IFS($A$3=1,Global!G29,$A$3=2,'North America'!G29,$A$3=3,APAC!G29,$A$3=4,Europe!G29,$A$3=5,'Latin America'!G29,$A$3=6,MEA!G29)} -> 365.97883 | H41: {=_xlfn.IFS($A$3=1,Global!H29,$A$3=2,'North America'!H29,$A$3=3,APAC!H29,$A$3=4,Europe!H29,$A$3=5,'Latin America'!H29,$A$3=6,MEA!H29)} -> 403.70283 | I41: {=_xlfn.IFS($A$3=1,Global!I29,$A$3=2,'North America'!I29,$A$3=3,APAC!I29,$A$3=4,Europe!I29,$A$3=5,'Latin America'!I29,$A$3=6,MEA!I29)} -> 445.59823 | J41: {=_xlfn.IFS($A$3=1,Global!J29,$A$3=2,'North America'!J29,$A$3=3,APAC!J29,$A$3=4,Europe!J29,$A$3=5,'Latin America'!J29,$A$3=6,MEA!J29)} -> 492.15938 | K41: {=_xlfn.IFS($A$3=1,Global!K29,$A$3=2,'North America'!K29,$A$3=3,APAC!K29,$A$3=4,Europe!K29,$A$3=5,'Latin America'!K29,$A$3=6,MEA!K29)} -> 543.94413 | ... Q41: {=_xlfn.IFS($A$3=1,Global!Q29,$A$3=2,'North America'!Q29,$A$3=3,APAC!Q29,$A$3=4,Europe!Q29,$A$3=5,'Latin America'!Q29,$A$3=6,MEA!Q29)} -> 1006.205 | R41: =RATE(9,,-H41,Q41) -> 0.10680066
A43: Disease Indication | B43: Lung cancer | D43: {=_xlfn.IFS($A$3=1,Global!D31,$A$3=2,'North America'!D31,$A$3=3,APAC!D31,$A$3=4,Europe!D31,$A$3=5,'Latin America'!D31,$A$3=6,MEA!D31)} -> 244.36425 | E43: {=_xlfn.IFS($A$3=1,Global!E31,$A$3=2,'North America'!E31,$A$3=3,APAC!E31,$A$3=4,Europe!E31,$A$3=5,'Latin America'!E31,$A$3=6,MEA!E31)} -> 271.62589 | F43: {=_xlfn.IFS($A$3=1,Global!F31,$A$3=2,'North America'!F31,$A$3=3,APAC!F31,$A$3=4,Europe!F31,$A$3=5,'Latin America'!F31,$A$3=6,MEA!F31)} -> 302.27421 | G43: {=_xlfn.IFS($A$3=1,Global!G31,$A$3=2,'North America'!G31,$A$3=3,APAC!G31,$A$3=4,Europe!G31,$A$3=5,'Latin America'!G31,$A$3=6,MEA!G31)} -> 336.7763 | H43: {=_xlfn.IFS($A$3=1,Global!H31,$A$3=2,'North America'!H31,$A$3=3,APAC!H31,$A$3=4,Europe!H31,$A$3=5,'Latin America'!H31,$A$3=6,MEA!H31)} -> 375.67123 | I43: {=_xlfn.IFS($A$3=1,Global!I31,$A$3=2,'North America'!I31,$A$3=3,APAC!I31,$A$3=4,Europe!I31,$A$3=5,'Latin America'!I31,$A$3=6,MEA!I31)} -> 419.58248 | J43: {=_xlfn.IFS($A$3=1,Global!J31,$A$3=2,'North America'!J31,$A$3=3,APAC!J31,$A$3=4,Europe!J31,$A$3=5,'Latin America'!J31,$A$3=6,MEA!J31)} -> 469.23293 | K43: {=_xlfn.IFS($A$3=1,Global!K31,$A$3=2,'North America'!K31,$A$3=3,APAC!K31,$A$3=4,Europe!K31,$A$3=5,'Latin America'!K31,$A$3=6,MEA!K31)} -> 525.46278 | ... Q43: {=_xlfn.IFS($A$3=1,Global!Q31,$A$3=2,'North America'!Q31,$A$3=3,APAC!Q31,$A$3=4,Europe!Q31,$A$3=5,'Latin America'!Q31,$A$3=6,MEA!Q31)} -> 1069.3967 | R43: =RATE(9,,-H43,Q43) -> 0.12326237
B44: Colorectal cancer | D44: {=_xlfn.IFS($A$3=1,Global!D32,$A$3=2,'North America'!D32,$A$3=3,APAC!D32,$A$3=4,Europe!D32,$A$3=5,'Latin America'!D32,$A$3=6,MEA!D32)} -> 195.4914 | E44: {=_xlfn.IFS($A$3=1,Global!E32,$A$3=2,'North America'!E32,$A$3=3,APAC!E32,$A$3=4,Europe!E32,$A$3=5,'Latin America'!E32,$A$3=6,MEA!E32)} -> 220.67226 | F44: {=_xlfn.IFS($A$3=1,Global!F32,$A$3=2,'North America'!F32,$A$3=3,APAC!F32,$A$3=4,Europe!F32,$A$3=5,'Latin America'!F32,$A$3=6,MEA!F32)} -> 249.38153 | G44: {=_xlfn.IFS($A$3=1,Global!G32,$A$3=2,'North America'!G32,$A$3=3,APAC!G32,$A$3=4,Europe!G32,$A$3=5,'Latin America'!G32,$A$3=6,MEA!G32)} -> 282.15731 | H44: {=_xlfn.IFS($A$3=1,Global!H32,$A$3=2,'North America'!H32,$A$3=3,APAC!H32,$A$3=4,Europe!H32,$A$3=5,'Latin America'!H32,$A$3=6,MEA!H32)} -> 319.62763 | I44: {=_xlfn.IFS($A$3=1,Global!I32,$A$3=2,'North America'!I32,$A$3=3,APAC!I32,$A$3=4,Europe!I32,$A$3=5,'Latin America'!I32,$A$3=6,MEA!I32)} -> 362.52698 | J44: {=_xlfn.IFS($A$3=1,Global!J32,$A$3=2,'North America'!J32,$A$3=3,APAC!J32,$A$3=4,Europe!J32,$A$3=5,'Latin America'!J32,$A$3=6,MEA!J32)} -> 411.7163 | K44: {=_xlfn.IFS($A$3=1,Global!K32,$A$3=2,'North America'!K32,$A$3=3,APAC!K32,$A$3=4,Europe!K32,$A$3=5,'Latin America'!K32,$A$3=6,MEA!K32)} -> 468.20726 | ... Q44: {=_xlfn.IFS($A$3=1,Global!Q32,$A$3=2,'North America'!Q32,$A$3=3,APAC!Q32,$A$3=4,Europe!Q32,$A$3=5,'Latin America'!Q32,$A$3=6,MEA!Q32)} -> 1045.0922 | R44: =RATE(9,,-H44,Q44) -> 0.14069046
B45: Breast cancer | D45: {=_xlfn.IFS($A$3=1,Global!D33,$A$3=2,'North America'!D33,$A$3=3,APAC!D33,$A$3=4,Europe!D33,$A$3=5,'Latin America'!D33,$A$3=6,MEA!D33)} -> 175.94226 | E45: {=_xlfn.IFS($A$3=1,Global!E33,$A$3=2,'North America'!E33,$A$3=3,APAC!E33,$A$3=4,Europe!E33,$A$3=5,'Latin America'!E33,$A$3=6,MEA!E33)} -> 197.67119 | F45: {=_xlfn.IFS($A$3=1,Global!F33,$A$3=2,'North America'!F33,$A$3=3,APAC!F33,$A$3=4,Europe!F33,$A$3=5,'Latin America'!F33,$A$3=6,MEA!F33)} -> 222.33765 | G45: {=_xlfn.IFS($A$3=1,Global!G33,$A$3=2,'North America'!G33,$A$3=3,APAC!G33,$A$3=4,Europe!G33,$A$3=5,'Latin America'!G33,$A$3=6,MEA!G33)} -> 250.37626 | H45: {=_xlfn.IFS($A$3=1,Global!H33,$A$3=2,'North America'!H33,$A$3=3,APAC!H33,$A$3=4,Europe!H33,$A$3=5,'Latin America'!H33,$A$3=6,MEA!H33)} -> 282.29245 | I45: {=_xlfn.IFS($A$3=1,Global!I33,$A$3=2,'North America'!I33,$A$3=3,APAC!I33,$A$3=4,Europe!I33,$A$3=5,'Latin America'!I33,$A$3=6,MEA!I33)} -> 318.67529 | J45: {=_xlfn.IFS($A$3=1,Global!J33,$A$3=2,'North America'!J33,$A$3=3,APAC!J33,$A$3=4,Europe!J33,$A$3=5,'Latin America'!J33,$A$3=6,MEA!J33)} -> 360.21287 | K45: {=_xlfn.IFS($A$3=1,Global!K33,$A$3=2,'North America'!K33,$A$3=3,APAC!K33,$A$3=4,Europe!K33,$A$3=5,'Latin America'!K33,$A$3=6,MEA!K33)} -> 407.71099 | ... Q45: {=_xlfn.IFS($A$3=1,Global!Q33,$A$3=2,'North America'!Q33,$A$3=3,APAC!Q33,$A$3=4,Europe!Q33,$A$3=5,'Latin America'!Q33,$A$3=6,MEA!Q33)} -> 884.68269 | R45: =RATE(9,,-H45,Q45) -> 0.13532687
B46: Prostate cancer | D46: {=_xlfn.IFS($A$3=1,Global!D34,$A$3=2,'North America'!D34,$A$3=3,APAC!D34,$A$3=4,Europe!D34,$A$3=5,'Latin America'!D34,$A$3=6,MEA!D34)} -> 117.29484 | E46: {=_xlfn.IFS($A$3=1,Global!E34,$A$3=2,'North America'!E34,$A$3=3,APAC!E34,$A$3=4,Europe!E34,$A$3=5,'Latin America'!E34,$A$3=6,MEA!E34)} -> 131.91916 | F46: {=_xlfn.IFS($A$3=1,Global!F34,$A$3=2,'North America'!F34,$A$3=3,APAC!F34,$A$3=4,Europe!F34,$A$3=5,'Latin America'!F34,$A$3=6,MEA!F34)} -> 148.53653 | G46: {=_xlfn.IFS($A$3=1,Global!G34,$A$3=2,'North America'!G34,$A$3=3,APAC!G34,$A$3=4,Europe!G34,$A$3=5,'Latin America'!G34,$A$3=6,MEA!G34)} -> 167.44385 | H46: {=_xlfn.IFS($A$3=1,Global!H34,$A$3=2,'North America'!H34,$A$3=3,APAC!H34,$A$3=4,Europe!H34,$A$3=5,'Latin America'!H34,$A$3=6,MEA!H34)} -> 188.98663 | I46: {=_xlfn.IFS($A$3=1,Global!I34,$A$3=2,'North America'!I34,$A$3=3,APAC!I34,$A$3=4,Europe!I34,$A$3=5,'Latin America'!I34,$A$3=6,MEA!I34)} -> 213.56789 | J46: {=_xlfn.IFS($A$3=1,Global!J34,$A$3=2,'North America'!J34,$A$3=3,APAC!J34,$A$3=4,Europe!J34,$A$3=5,'Latin America'!J34,$A$3=6,MEA!J34)} -> 241.65878 | K46: {=_xlfn.IFS($A$3=1,Global!K34,$A$3=2,'North America'!K34,$A$3=3,APAC!K34,$A$3=4,Europe!K34,$A$3=5,'Latin America'!K34,$A$3=6,MEA!K34)} -> 273.8114 | ... Q46: {=_xlfn.IFS($A$3=1,Global!Q34,$A$3=2,'North America'!Q34,$A$3=3,APAC!Q34,$A$3=4,Europe!Q34,$A$3=5,'Latin America'!Q34,$A$3=6,MEA!Q34)} -> 597.88995 | R46: =RATE(9,,-H46,Q46) -> 0.13651896
B47: Liver cancer | D47: {=_xlfn.IFS($A$3=1,Global!D35,$A$3=2,'North America'!D35,$A$3=3,APAC!D35,$A$3=4,Europe!D35,$A$3=5,'Latin America'!D35,$A$3=6,MEA!D35)} -> 97.7457 | E47: {=_xlfn.IFS($A$3=1,Global!E35,$A$3=2,'North America'!E35,$A$3=3,APAC!E35,$A$3=4,Europe!E35,$A$3=5,'Latin America'!E35,$A$3=6,MEA!E35)} -> 110.1366 | F47: {=_xlfn.IFS($A$3=1,Global!F35,$A$3=2,'North America'!F35,$A$3=3,APAC!F35,$A$3=4,Europe!F35,$A$3=5,'Latin America'!F35,$A$3=6,MEA!F35)} -> 124.24019 | G47: {=_xlfn.IFS($A$3=1,Global!G35,$A$3=2,'North America'!G35,$A$3=3,APAC!G35,$A$3=4,Europe!G35,$A$3=5,'Latin America'!G35,$A$3=6,MEA!G35)} -> 140.31466 | H47: {=_xlfn.IFS($A$3=1,Global!H35,$A$3=2,'North America'!H35,$A$3=3,APAC!H35,$A$3=4,Europe!H35,$A$3=5,'Latin America'!H35,$A$3=6,MEA!H35)} -> 158.66092 | I47: {=_xlfn.IFS($A$3=1,Global!I35,$A$3=2,'North America'!I35,$A$3=3,APAC!I35,$A$3=4,Europe!I35,$A$3=5,'Latin America'!I35,$A$3=6,MEA!I35)} -> 179.63042 | J47: {=_xlfn.IFS($A$3=1,Global!J35,$A$3=2,'North America'!J35,$A$3=3,APAC!J35,$A$3=4,Europe!J35,$A$3=5,'Latin America'!J35,$A$3=6,MEA!J35)} -> 203.63458 | K47: {=_xlfn.IFS($A$3=1,Global!K35,$A$3=2,'North America'!K35,$A$3=3,APAC!K35,$A$3=4,Europe!K35,$A$3=5,'Latin America'!K35,$A$3=6,MEA!K35)} -> 231.15619 | ... Q47: {=_xlfn.IFS($A$3=1,Global!Q35,$A$3=2,'North America'!Q35,$A$3=3,APAC!Q35,$A$3=4,Europe!Q35,$A$3=5,'Latin America'!Q35,$A$3=6,MEA!Q35)} -> 510.39386 | R47: =RATE(9,,-H47,Q47) -> 0.13862763
B48: Head & neck cancer | D48: {=_xlfn.IFS($A$3=1,Global!D36,$A$3=2,'North America'!D36,$A$3=3,APAC!D36,$A$3=4,Europe!D36,$A$3=5,'Latin America'!D36,$A$3=6,MEA!D36)} -> 127.06941 | E48: {=_xlfn.IFS($A$3=1,Global!E36,$A$3=2,'North America'!E36,$A$3=3,APAC!E36,$A$3=4,Europe!E36,$A$3=5,'Latin America'!E36,$A$3=6,MEA!E36)} -> 142.97414 | F48: {=_xlfn.IFS($A$3=1,Global!F36,$A$3=2,'North America'!F36,$A$3=3,APAC!F36,$A$3=4,Europe!F36,$A$3=5,'Latin America'!F36,$A$3=6,MEA!F36)} -> 161.05359 | G48: {=_xlfn.IFS($A$3=1,Global!G36,$A$3=2,'North America'!G36,$A$3=3,APAC!G36,$A$3=4,Europe!G36,$A$3=5,'Latin America'!G36,$A$3=6,MEA!G36)} -> 181.63261 | H48: {=_xlfn.IFS($A$3=1,Global!H36,$A$3=2,'North America'!H36,$A$3=3,APAC!H36,$A$3=4,Europe!H36,$A$3=5,'Latin America'!H36,$A$3=6,MEA!H36)} -> 205.0894 | I48: {=_xlfn.IFS($A$3=1,Global!I36,$A$3=2,'North America'!I36,$A$3=3,APAC!I36,$A$3=4,Europe!I36,$A$3=5,'Latin America'!I36,$A$3=6,MEA!I36)} -> 231.86522 | J48: {=_xlfn.IFS($A$3=1,Global!J36,$A$3=2,'North America'!J36,$A$3=3,APAC!J36,$A$3=4,Europe!J36,$A$3=5,'Latin America'!J36,$A$3=6,MEA!J36)} -> 262.47607 | K48: {=_xlfn.IFS($A$3=1,Global!K36,$A$3=2,'North America'!K36,$A$3=3,APAC!K36,$A$3=4,Europe!K36,$A$3=5,'Latin America'!K36,$A$3=6,MEA!K36)} -> 297.52686 | ... Q48: {=_xlfn.IFS($A$3=1,Global!Q36,$A$3=2,'North America'!Q36,$A$3=3,APAC!Q36,$A$3=4,Europe!Q36,$A$3=5,'Latin America'!Q36,$A$3=6,MEA!Q36)} -> 651.35978 | R48: =RATE(9,,-H48,Q48) -> 0.13700976
B49: Others cancers | D49: {=_xlfn.IFS($A$3=1,Global!D37,$A$3=2,'North America'!D37,$A$3=3,APAC!D37,$A$3=4,Europe!D37,$A$3=5,'Latin America'!D37,$A$3=6,MEA!D37)} -> 19.54914 | E49: {=_xlfn.IFS($A$3=1,Global!E37,$A$3=2,'North America'!E37,$A$3=3,APAC!E37,$A$3=4,Europe!E37,$A$3=5,'Latin America'!E37,$A$3=6,MEA!E37)} -> 22.240981 | F49: {=_xlfn.IFS($A$3=1,Global!F37,$A$3=2,'North America'!F37,$A$3=3,APAC!F37,$A$3=4,Europe!F37,$A$3=5,'Latin America'!F37,$A$3=6,MEA!F37)} -> 25.287421 | G49: {=_xlfn.IFS($A$3=1,Global!G37,$A$3=2,'North America'!G37,$A$3=3,APAC!G37,$A$3=4,Europe!G37,$A$3=5,'Latin America'!G37,$A$3=6,MEA!G37)} -> 28.735806 | H49: {=_xlfn.IFS($A$3=1,Global!H37,$A$3=2,'North America'!H37,$A$3=3,APAC!H37,$A$3=4,Europe!H37,$A$3=5,'Latin America'!H37,$A$3=6,MEA!H37)} -> 32.640082 | I49: {=_xlfn.IFS($A$3=1,Global!I37,$A$3=2,'North America'!I37,$A$3=3,APAC!I37,$A$3=4,Europe!I37,$A$3=5,'Latin America'!I37,$A$3=6,MEA!I37)} -> 37.061783 | J49: {=_xlfn.IFS($A$3=1,Global!J37,$A$3=2,'North America'!J37,$A$3=3,APAC!J37,$A$3=4,Europe!J37,$A$3=5,'Latin America'!J37,$A$3=6,MEA!J37)} -> 42.071188 | K49: {=_xlfn.IFS($A$3=1,Global!K37,$A$3=2,'North America'!K37,$A$3=3,APAC!K37,$A$3=4,Europe!K37,$A$3=5,'Latin America'!K37,$A$3=6,MEA!K37)} -> 47.748665 | ... Q49: {=_xlfn.IFS($A$3=1,Global!Q37,$A$3=2,'North America'!Q37,$A$3=3,APAC!Q37,$A$3=4,Europe!Q37,$A$3=5,'Latin America'!Q37,$A$3=6,MEA!Q37)} -> 102.07877 | R49: =RATE(9,,-H49,Q49) -> 0.13506431

Sheet Europe
A2: Europe Liquid Biopsy Market, 2027-36 (USD Million)
D13: 2023 | E13: 2024 | F13: 2025 | G13: 2026 | H13: 2027 | I13: 2028 | J13: 2029 | K13: 2030 | L13: 2031 | M13: 2032 | N13: 2033 | O13: 2034 | P13: 2035 | Q13: 2036 | R13: CAGR (2027-2036)
D14: =SUM(D63+D113+D163+D212+D261+D310+D359+D408) -> 1170.195 | E14: =SUM(E63+E113+E163+E212+E261+E310+E359+E408) -> 1300.5711 | F14: =SUM(F63+F113+F163+F212+F261+F310+F359+F408) -> 1447.4534 | G14: =SUM(G63+G113+G163+G212+G261+G310+G359+G408) -> 1613.0827 | H14: =SUM(H63+H113+H163+H212+H261+H310+H359+H408) -> 1800.0211 | I14: =SUM(I63+I113+I163+I212+I261+I310+I359+I408) -> 2011.1998 | J14: =SUM(J63+J113+J163+J212+J261+J310+J359+J408) -> 2249.9752 | K14: =SUM(K63+K113+K163+K212+K261+K310+K359+K408) -> 2520.1933 | ... Q14: =SUM(Q63+Q113+Q163+Q212+Q261+Q310+Q359+Q408) -> 5100.543 | R14: =RATE(9,,-H14,Q14) -> 0.12269004 | T14: 2023 | U14: 2024 | V14: 2025 | W14: 2026 | X14: 2027 | Y14: 2028 | Z14: 2029 | AA14: 2030 | AB14: 2031 | AC14: 2032 | AD14: 2033 | AE14: 2034 | AF14: 2035 | AG14: 2036
A15: Biomarker Type | B15: Circulating tumor cells | D15: =D14*T15 -> 351.0585 | E15: =E14*U15 -> 394.82542 | F15: =F14*V15 -> 444.65722 | G15: =G14*W15 -> 501.44944 | H15: =H14*X15 -> 566.23651 | I15: =I14*Y15 -> 640.21412 | J15: =J14*Z15 -> 724.76549 | K15: =K14*AA15 -> 821.49208 | ... Q15: =Q14*AG15 -> 1785.19 | R15: =RATE(9,,-H15,Q15) -> 0.13608185 | S15: Circulating tumor cells | T15: 0.3 | U15: 0.3035785 | V15: 0.30719968 | W15: 0.31086406 | X15: 0.31457215 | Y15: 0.31832447 | Z15: 0.32212154 | AA15: 0.32596392 | AB15: 0.32985212 | AC15: 0.3337867 | AD15: 0.33776822 | AE15: 0.34179723 | AF15: 0.3458743 | AG15: 0.35
B16: Circulating tumor DNA | D16: =D14*T16 -> 234.039 | E16: =E14*U16 -> 261.09229 | F16: =F14*V16 -> 291.67182 | G16: =G14*W16 -> 326.2695 | H16: =H14*X16 -> 365.44951 | I16: =I14*Y16 -> 409.85945 | J16: =J14*Z16 -> 460.24323 | K16: =K14*AA16 -> 517.45605 | ... Q16: =Q14*AG16 -> 1071.114 | R16: =RATE(9,,-H16,Q16) -> 0.12691151 | S16: Circulating tumor DNA | T16: 0.2 | U16: 0.20075203 | V16: 0.20150688 | W16: 0.20226458 | X16: 0.20302512 | Y16: 0.20378853 | Z16: 0.2045548 | AA16: 0.20532395 | AB16: 0.206096 | AC16: 0.20687095 | AD16: 0.20764881 | AE16: 0.2084296 | AF16: 0.20921333 | AG16: 0.21
B17: Exosomes | D17: =D14*T17 -> 117.0195 | E17: =E14*U17 -> 131.89398 | F17: =F14*V17 -> 148.86285 | G17: =G14*W17 -> 168.23999 | H17: =H14*X17 -> 190.38865 | I17: =I14*Y17 -> 215.72951 | J17: =J14*Z17 -> 244.75013 | K17: =K14*AA17 -> 278.01608 | ... Q17: =Q14*AG17 -> 612.06516 | R17: =RATE(9,,-H17,Q17) -> 0.1385464 | S17: Exosomes | T17: 0.1 | U17: 0.10141235 | V17: 0.10284466 | W17: 0.10429719 | X17: 0.10577023 | Y17: 0.10726408 | Z17: 0.10877903 | AA17: 0.11031538 | AB17: 0.11187342 | AC17: 0.11345347 | AD17: 0.11505584 | AE17: 0.11668083 | AF17: 0.11832878 | AG17: 0.12
B18: Circulating RNA & proteins | D18: =D14*T18 -> 81.91365 | E18: =E14*U18 -> 91.524424 | F18: =F14*V18 -> 102.40292 | G18: =G14*W18 -> 114.72796 | H18: =H14*X18 -> 128.7049 | I18: =I14*Y18 -> 144.5698 | J18: =J14*Z18 -> 162.59416 | K18: =K14*AA18 -> 183.09055 | ... Q18: =Q14*AG18 -> 382.54072 | R18: =RATE(9,,-H18,Q18) -> 0.12866415 | S18: Circulating RNA & proteins | T18: 0.07 | U18: 0.070372488 | V18: 0.070746957 | W18: 0.07112342 | X18: 0.071501885 | Y18: 0.071882365 | Z18: 0.072264869 | AA18: 0.072649409 | AB18: 0.073035994 | AC18: 0.073424637 | AD18: 0.073815348 | AE18: 0.074208138 | AF18: 0.074603019 | AG18: 0.075
B19: Nucleosomes | D19: =D14*T19 -> 386.16435 | E19: =E14*U19 -> 421.23499 | F19: =F14*V19 -> 459.85857 | G19: =G14*W19 -> 502.39583 | H19: =H14*X19 -> 549.24155 | I19: =I14*Y19 -> 600.82697 | J19: =J14*Z19 -> 657.6222 | K19: =K14*AA19 -> 720.13855 | ... Q19: =Q14*AG19 -> 1249.633 | R19: =RATE(9,,-H19,Q19) -> 0.095642299 | S19: Nucleosomes | T19: =1-SUM(T15:T18) -> 0.33 | U19: =1-SUM(U15:U18) -> 0.32388463 | V19: =1-SUM(V15:V18) -> 0.31770182 | W19: =1-SUM(W15:W18) -> 0.31145076 | X19: =1-SUM(X15:X18) -> 0.30513061 | Y19: =1-SUM(Y15:Y18) -> 0.29874056 | Z19: =1-SUM(Z15:Z18) -> 0.29227976 | AA19: =1-SUM(AA15:AA18) -> 0.28574734 | ... AG19: =1-SUM(AG15:AG18) -> 0.245
D20: =D14=SUM(D15:D19) -> TRUE | E20: =E14=SUM(E15:E19) -> TRUE | F20: =F14=SUM(F15:F19) -> TRUE | G20: =G14=SUM(G15:G19) -> TRUE | H20: =H14=SUM(H15:H19) -> TRUE | I20: =I14=SUM(I15:I19) -> TRUE | J20: =J14=SUM(J15:J19) -> TRUE | K20: =K14=SUM(K15:K19) -> TRUE | ... Q20: =Q14=SUM(Q15:Q19) -> TRUE
A21: Sample | B21: Blood | D21: =D14*T21 -> 819.1365 | E21: =E14*U21 -> 910.49982 | F21: =F14*V21 -> 1013.4401 | G21: =G14*W21 -> 1129.5302 | H21: =H14*X21 -> 1260.5686 | I21: =I14*Y21 -> 1408.6134 | J21: =J14*Z21 -> 1576.0211 | K21: =K14*AA21 -> 1765.4923 | ... Q21: =Q14*AG21 -> 3575.4806 | R21: =RATE(9,,-H21,Q21) -> 0.1228133 | S21: Blood | T21: 0.7 | U21: 0.70007692 | V21: 0.70015385 | W21: 0.70023077 | X21: 0.70030769 | Y21: 0.70038462 | Z21: 0.70046154 | AA21: 0.70053846 | AB21: 0.70061538 | AC21: 0.70069231 | AD21: 0.70076923 | AE21: 0.70084615 | AF21: 0.70092308 | AG21: 0.701
B22: Urine | D22: =D14*T22 -> 234.039 | E22: =E14*U22 -> 260.21427 | F22: =F14*V22 -> 289.71336 | G22: =G14*W22 -> 322.9888 | H22: =H14*X22 -> 360.55808 | I22: =I14*Y22 -> 403.01351 | J22: =J14*Z22 -> 451.03349 | K22: =K14*AA22 -> 505.39569 | ... Q22: =Q14*AG22 -> 1025.2091 | R22: =RATE(9,,-H22,Q22) -> 0.12312051 | S22: Urine | T22: 0.2 | U22: 0.20007692 | V22: 0.20015385 | W22: 0.20023077 | X22: 0.20030769 | Y22: 0.20038462 | Z22: 0.20046154 | AA22: 0.20053846 | AB22: 0.20061538 | AC22: 0.20069231 | AD22: 0.20076923 | AE22: 0.20084615 | AF22: 0.20092308 | AG22: 0.201
B23: Others (Serum) | D23: =D14*T23 -> 117.0195 | E23: =E14*U23 -> 129.85702 | F23: =F14*V23 -> 144.29997 | G23: =G14*W23 -> 160.56377 | H23: =H14*X23 -> 178.89441 | I23: =I14*Y23 -> 199.57291 | J23: =J14*Z23 -> 222.92062 | K23: =K14*AA23 -> 249.30528 | ... Q23: =Q14*AG23 -> 499.85321 | R23: =RATE(9,,-H23,Q23) -> 0.12094127 | S23: Others (Serum) | T23: =1-SUM(T21:T22) -> 0.1 | U23: =1-SUM(U21:U22) -> 0.099846154 | V23: =1-SUM(V21:V22) -> 0.099692308 | W23: =1-SUM(W21:W22) -> 0.099538462 | X23: =1-SUM(X21:X22) -> 0.099384615 | Y23: =1-SUM(Y21:Y22) -> 0.099230769 | Z23: =1-SUM(Z21:Z22) -> 0.099076923 | AA23: =1-SUM(AA21:AA22) -> 0.098923077 | ... AG23: =1-SUM(AG21:AG22) -> 0.098
D24: =D14=SUM(D21:D23) -> TRUE | E24: =E14=SUM(E21:E23) -> TRUE | F24: =F14=SUM(F21:F23) -> TRUE | G24: =G14=SUM(G21:G23) -> TRUE | H24: =H14=SUM(H21:H23) -> TRUE | I24: =I14=SUM(I21:I23) -> TRUE | J24: =J14=SUM(J21:J23) -> TRUE | K24: =K14=SUM(K21:K23) -> TRUE | ... Q24: =Q14=SUM(Q21:Q23) -> TRUE
A25: Clinical Application | B25: Early disease screening | D25: =D14*T25 -> 351.0585 | E25: =E14*U25 -> 393.31611 | F25: =F14*V25 -> 441.26411 | G25: =G14*W25 -> 495.72069 | H25: =H14*X25 -> 557.62776 | I25: =I14*Y25 -> 628.0705 | J25: =J14*Z25 -> 708.30007 | K25: =K14*AA25 -> 799.7602 | ... Q25: =Q14*AG25 -> 1698.4808 | R25: =RATE(9,,-H25,Q25) -> 0.13173892 | S25: Early disease screening | T25: 0.3 | U25: 0.302418 | V25: 0.30485549 | W25: 0.30731263 | X25: 0.30978957 | Y25: 0.31228647 | Z25: 0.3148035 | AA25: 0.31734082 | AB25: 0.31989858 | AC25: 0.32247697 | AD25: 0.32507613 | AE25: 0.32769625 | AF25: 0.33033748 | AG25: 0.333
B26: Therapy selection | D26: =D14*T26 -> 234.039 | E26: =E14*U26 -> 262.02827 | F26: =F14*V26 -> 293.76678 | G26: =G14*W26 -> 329.791 | H26: =H14*X26 -> 370.71812 | I26: =I14*Y26 -> 417.25878 | J26: =J14*Z26 -> 470.23185 | K26: =K14*AA26 -> 530.58164 | ... Q26: =Q14*AG26 -> 1122.1195 | R26: =RATE(9,,-H26,Q26) -> 0.13095134 | S26: Therapy selection | T26: 0.2 | U26: 0.2014717 | V26: 0.20295423 | W26: 0.20444766 | X26: 0.20595209 | Y26: 0.20746759 | Z26: 0.20899424 | AA26: 0.21053212 | AB26: 0.21208132 | AC26: 0.21364192 | AD26: 0.215214 | AE26: 0.21679765 | AF26: 0.21839296 | AG26: 0.22
B27: Treatment response monitoring | D27: =D14*T27 -> 175.52925 | E27: =E14*U27 -> 196.5212 | F27: =F14*V27 -> 220.32509 | G27: =G14*W27 -> 247.34325 | H27: =H14*X27 -> 278.03859 | I27: =I14*Y27 -> 312.94409 | J27: =J14*Z27 -> 352.67389 | K27: =K14*AA27 -> 397.93623 | ... Q27: =Q14*AG27 -> 841.58959 | R27: =RATE(9,,-H27,Q27) -> 0.13095134 | S27: Treatment response monitoring | T27: 0.15 | U27: 0.15110377 | V27: 0.15221567 | W27: 0.15333575 | X27: 0.15446407 | Y27: 0.15560069 | Z27: 0.15674568 | AA27: 0.15789909 | AB27: 0.15906099 | AC27: 0.16023144 | AD27: 0.1614105 | AE27: 0.16259824 | AF27: 0.16379472 | AG27: 0.165
B28: Molecular health monitoring | D28: =D14*T28 -> 81.91365 | E28: =E14*U28 -> 91.524424 | F28: =F14*V28 -> 102.40292 | G28: =G14*W28 -> 114.72796 | H28: =H14*X28 -> 128.7049 | I28: =I14*Y28 -> 144.5698 | J28: =J14*Z28 -> 162.59416 | K28: =K14*AA28 -> 183.09055 | ... Q28: =Q14*AG28 -> 382.54072 | R28: =RATE(9,,-H28,Q28) -> 0.12866415 | S28: Molecular health monitoring | T28: 0.07 | U28: 0.070372488 | V28: 0.070746957 | W28: 0.07112342 | X28: 0.071501885 | Y28: 0.071882365 | Z28: 0.072264869 | AA28: 0.072649409 | AB28: 0.073035994 | AC28: 0.073424637 | AD28: 0.073815348 | AE28: 0.074208138 | AF28: 0.074603019 | AG28: 0.075
B29: Others | D29: =D14*T29 -> 327.6546 | E29: =E14*U29 -> 357.1811 | F29: =F14*V29 -> 389.69448 | G29: =G14*W29 -> 425.49984 | H29: =H14*X29 -> 464.93176 | I29: =I14*Y29 -> 508.35667 | J29: =J14*Z29 -> 556.17523 | K29: =K14*AA29 -> 608.82468 | ... Q29: =Q14*AG29 -> 1055.8124 | R29: =RATE(9,,-H29,Q29) -> 0.095412028 | S29: Others | T29: =1-SUM(T25:T28) -> 0.28 | U29: =1-SUM(U25:U28) -> 0.27463404 | V29: =1-SUM(V25:V28) -> 0.26922766 | W29: =1-SUM(W25:W28) -> 0.26378054 | X29: =1-SUM(X25:X28) -> 0.25829239 | Y29: =1-SUM(Y25:Y28) -> 0.25276288 | Z29: =1-SUM(Z25:Z28) -> 0.24719171 | AA29: =1-SUM(AA25:AA28) -> 0.24157856 | ... AG29: =1-SUM(AG25:AG28) -> 0.207
D30: =D14=SUM(D25:D29) -> TRUE | E30: =E14=SUM(E25:E29) -> TRUE | F30: =F14=SUM(F25:F29) -> TRUE | G30: =G14=SUM(G25:G29) -> TRUE | H30: =H14=SUM(H25:H29) -> TRUE | I30: =I14=SUM(I25:I29) -> TRUE | J30: =J14=SUM(J25:J29) -> TRUE | K30: =K14=SUM(K25:K29) -> TRUE | ... Q30: =Q14=SUM(Q25:Q29) -> TRUE
A31: Disease Indication | B31: Lung cancer | D31: =D14*T31 -> 292.54875 | E31: =E14*U31 -> 321.96121 | F31: =F14*V31 -> 354.81622 | G31: =G14*W31 -> 391.54795 | H31: =H14*X31 -> 432.64865 | I31: =I14*Y31 -> 478.67684 | J31: =J14*Z31 -> 530.26671 | K31: =K14*AA31 -> 588.13892 | ... Q31: =Q14*AG31 -> 1122.1195 | R31: =RATE(9,,-H31,Q31) -> 0.11170435 | S31: Lung cancer | T31: 0.25 | U31: 0.24755371 | V31: 0.24513136 | W31: 0.24273272 | X31: 0.24035754 | Y31: 0.23800561 | Z31: 0.23567669 | AA31: 0.23337056 | AB31: 0.23108699 | AC31: 0.22882577 | AD31: 0.22658668 | AE31: 0.22436949 | AF31: 0.22217401 | AG31: 0.22
B32: Colorectal cancer | D32: =D14*T32 -> 234.039 | E32: =E14*U32 -> 261.5653 | F32: =F14*V32 -> 292.72961 | G32: =G14*W32 -> 328.046 | H32: =H14*X32 -> 368.10502 | I32: =I14*Y32 -> 413.58559 | J32: =J14*Z32 -> 465.26881 | K32: =K14*AA32 -> 524.05407 | ... Q32: =Q14*AG32 -> 1096.6167 | R32: =RATE(9,,-H32,Q32) -> 0.12895311 | S32: Colorectal cancer | T32: 0.2 | U32: 0.20111573 | V32: 0.20223768 | W32: 0.20336589 | X32: 0.20450039 | Y32: 0.20564122 | Z32: 0.20678842 | AA32: 0.20794201 | AB32: 0.20910205 | AC32: 0.21026855 | AD32: 0.21144156 | AE32: 0.21262111 | AF32: 0.21380725 | AG32: 0.215
B33: Breast cancer | D33: =D14*T33 -> 210.6351 | E33: =E14*U33 -> 234.30187 | F33: =F14*V33 -> 260.9849 | G33: =G14*W33 -> 291.09623 | H33: =H14*X33 -> 325.10727 | I33: =I14*Y33 -> 363.55779 | J33: =J14*Z33 -> 407.06626 | K33: =K14*AA33 -> 456.34193 | ... Q33: =Q14*AG33 -> 928.29882 | R33: =RATE(9,,-H33,Q33) -> 0.12364471 | S33: Breast cancer | T33: 0.18 | U33: 0.18015306 | V33: 0.18030626 | W33: 0.18045958 | X33: 0.18061303 | Y33: 0.18076662 | Z33: 0.18092033 | AA33: 0.18107418 | AB33: 0.18122815 | AC33: 0.18138226 | AD33: 0.1815365 | AE33: 0.18169087 | AF33: 0.18184537 | AG33: 0.182
B34: Prostate cancer | D34: =D14*T34 -> 140.4234 | E34: =E14*U34 -> 156.36526 | F34: =F14*V34 -> 174.3555 | G34: =G14*W34 -> 194.67609 | H34: =H14*X34 -> 217.64991 | I34: =I14*Y34 -> 243.64698 | J34: =J14*Z34 -> 273.09167 | K34: =K14*AA34 -> 306.47107 | ... Q34: =Q14*AG34 -> 627.36679 | R34: =RATE(9,,-H34,Q34) -> 0.12482453 | S34: Prostate cancer | T34: 0.12 | U34: 0.12022815 | V34: 0.12045673 | W34: 0.12068575 | X34: 0.1209152 | Y34: 0.12114509 | Z34: 0.12137541 | AA34: 0.12160618 | AB34: 0.12183738 | AC34: 0.12206902 | AD34: 0.1223011 | AE34: 0.12253363 | AF34: 0.12276659 | AG34: 0.123
B35: Liver cancer | D35: =D14*T35 -> 117.0195 | E35: =E14*U35 -> 130.54614 | F35: =F14*V35 -> 145.83591 | G35: =G14*W35 -> 163.13475 | H35: =H14*X35 -> 182.72475 | I35: =I14*Y35 -> 204.92972 | J35: =J14*Z35 -> 230.12161 | K35: =K14*AA35 -> 258.72803 | ... Q35: =Q14*AG35 -> 535.55701 | R35: =RATE(9,,-H35,Q35) -> 0.12691151 | S35: Liver cancer | T35: 0.1 | U35: 0.10037601 | V35: 0.10075344 | W35: 0.10113229 | X35: 0.10151256 | Y35: 0.10189426 | Z35: 0.1022774 | AA35: 0.10266198 | AB35: 0.103048 | AC35: 0.10343548 | AD35: 0.10382441 | AE35: 0.1042148 | AF35: 0.10460666 | AG35: 0.105
